<?xml version="1.0" ?>
<!-- =================================================================================== -->
<!-- |    This document was autogenerated by xacro from laser.xacro                    | -->
<!-- |    EDITING THIS FILE BY HAND IS NOT RECOMMENDED                                 | -->
<!-- =================================================================================== -->
<robot name="basic_robot" xmlns:controller="http://playerstage.sourceforge.net/gazebo/xmlschema/#controller" xmlns:interface="http://playerstage.sourceforge.net/gazebo/xmlschema/#interface" xmlns:sensor="http://playerstage.sourceforge.net/gazebo/xmlschema/#sensor">
  <gazebo reference="base_link">
    <material>Gazebo/Orange</material>
  </gazebo>
  <gazebo reference="front_left_wheel">
    <material>Gazebo/Black</material>
    <kp value="100000000.0"/>
    <kd value="1"/>
    <minDepth value="0.005"/>
    <mu1 value="1"/>
    <!-- 2.0 -->
    <mu2 value="1"/>
    <!-- 0.5 -->
    <fdir1 value="1 0 0"/>
    <turnGravityOff>false</turnGravityOff>
    <dampingFactor>0.01</dampingFactor>
  </gazebo>
  <gazebo reference="back_left_wheel">
    <material>Gazebo/Black</material>
    <kp value="100000000.0"/>
    <kd value="1"/>
    <minDepth value="0.005"/>
    <mu1 value="1"/>
    <!-- 2.0 -->
    <mu2 value="1"/>
    <!-- 0.5 -->
    <fdir1 value="1 0 0"/>
    <turnGravityOff>false</turnGravityOff>
    <dampingFactor>0.01</dampingFactor>
  </gazebo>
  <gazebo reference="front_right_wheel">
    <material>Gazebo/Black</material>
    <kp value="100000000.0"/>
    <kd value="1"/>
    <minDepth value="0.005"/>
    <mu1 value="1"/>
    <!-- 2.0 -->
    <mu2 value="1"/>
    <!-- 0.5 -->
    <fdir1 value="1 0 0"/>
    <turnGravityOff>false</turnGravityOff>
    <dampingFactor>0.01</dampingFactor>
  </gazebo>
  <gazebo reference="back_right_wheel">
    <material>Gazebo/Black</material>
    <kp value="100000000.0"/>
    <kd value="1"/>
    <minDepth value="0.005"/>
    <mu1 value="1"/>
    <!-- 2.0 -->
    <mu2 value="1"/>
    <!-- 0.5 -->
    <fdir1 value="1 0 0"/>
    <turnGravityOff>false</turnGravityOff>
    <dampingFactor>0.01</dampingFactor>
  </gazebo>
  <!-- hokuyo -->
  <gazebo reference="hokuyo_link">
    <sensor name="head_hokuyo_sensor" type="ray">
      <pose>0 0 0 0 0 0</pose>
      <visualize>true</visualize>
      <update_rate>40</update_rate>
      <ray>
        <scan>
          <horizontal>
            <samples>720</samples>
            <resolution>1</resolution>
            <min_angle>-1.570796</min_angle>
            <max_angle>1.570796</max_angle>
          </horizontal>
        </scan>
        <range>
          <min>0.10</min>
          <max>30.0</max>
          <resolution>0.01</resolution>
        </range>
        <noise>
          <type>gaussian</type>
          <!-- Noise parameters based on published spec for Hokuyo laser
               achieving "+-30mm" accuracy at range < 10m.  A mean of 0.0m and
               stddev of 0.01m will put 99.7% of samples within 0.03m of the true
               reading. -->
          <mean>0.0</mean>
          <stddev>0.01</stddev>
        </noise>
      </ray>
      <plugin filename="libgazebo_ros_laser.so" name="gazebo_ros_head_hokuyo_controller">
        <topicName>/robot/laser/scan</topicName>
        <frameName>hokuyo_link</frameName>
      </plugin>
    </sensor>
  </gazebo>
  <transmission name="front_left_wheel_trans">
    <type>transmission_interface/SimpleTransmission</type>
    <actuator name="front_left_wheel_motor">
      <hardwareInterface>velocityJointInterface</hardwareInterface>
      <mechanicalReduction>1</mechanicalReduction>
    </actuator>
    <joint name="base_to_front_left_wheel">
      <hardwareInterface>VelocityJointInterface</hardwareInterface>
      <mechanicalReduction>1.0</mechanicalReduction>
    </joint>
  </transmission>
  <transmission name="front_right_wheel_trans">
    <type>transmission_interface/SimpleTransmission</type>
    <actuator name="front_right_wheel_motor">
      <hardwareInterface>velocityJointInterface</hardwareInterface>
      <mechanicalReduction>1</mechanicalReduction>
    </actuator>
    <joint name="base_to_front_right_wheel">
      <hardwareInterface>VelocityJointInterface</hardwareInterface>
      <mechanicalReduction>1.0</mechanicalReduction>
    </joint>
  </transmission>
  <transmission name="back_left_wheel_trans">
    <type>transmission_interface/SimpleTransmission</type>
    <actuator name="back_left_wheel_motor">
      <hardwareInterface>velocityJointInterface</hardwareInterface>
      <mechanicalReduction>1</mechanicalReduction>
    </actuator>
    <joint name="base_to_back_left_wheel">
      <hardwareInterface>VelocityJointInterface</hardwareInterface>
      <mechanicalReduction>1.0</mechanicalReduction>
    </joint>
  </transmission>
  <transmission name="back_right_wheel_trans">
    <type>transmission_interface/SimpleTransmission</type>
    <actuator name="back_right_wheel_motor">
      <hardwareInterface>velocityJointInterface</hardwareInterface>
      <mechanicalReduction>1</mechanicalReduction>
    </actuator>
    <joint name="base_to_back_right_wheel">
      <hardwareInterface>VelocityJointInterface</hardwareInterface>
      <mechanicalReduction>1.0</mechanicalReduction>
    </joint>
  </transmission>
  <plugin filename="skid_steer_drive/libDdsSkidSteerDrivePlugin.so" name="SkidSteerDrivePlugin">
    <dds_domain_id>0</dds_domain_id>
    <topic_name_twist>cmd_vel</topic_name_twist>
    <topic_name_odometry>odom</topic_name_odometry>
    <topic_name_joint>joint</topic_name_joint>
    <right_front_joint>base_to_front_right_wheel</right_front_joint>
    <right_rear_joint>base_to_back_right_wheel</right_rear_joint>
    <left_front_joint>base_to_front_left_wheel</left_front_joint>
    <left_rear_joint>base_to_back_left_wheel</left_rear_joint>
    <wheel_separation>0.1</wheel_separation>
    <wheel_diameter>0.15</wheel_diameter>
    <wheel_torque>1</wheel_torque>
    <update_rate>2</update_rate>
  </plugin>
  <gazebo>
    <plugin filename="libgazebo_ros_control.so" name="gazebo_ros_control">
    </plugin>
  </gazebo>
  <plugin filename="skid_steer_drive/libDdsSkidSteerDrivePlugin.so" name="SkidSteerDrivePlugin">
    <!-- ... -->
  </plugin>
  <link name="base_footprint">
    <visual>
      <geometry>
        <box size="0.001 0.001 0.001"/>
      </geometry>
      <origin rpy="0 0 0" xyz="0 0 0"/>
    </visual>
    
  </link>
  <gazebo reference="base_footprint">
    <material>Gazebo/Green</material>
    <turnGravityOff>false</turnGravityOff>
  </gazebo>
  <joint name="base_footprint_joint" type="fixed">
    <origin xyz="0 0 0"/>
    <parent link="base_footprint"/>
    <child link="base_link"/>
  </joint>
  <link name="base_link">
    <visual>
      <geometry>
        <box size="0.2 .3 .1"/>
      </geometry>
      <origin rpy="0 0 1.54" xyz="0 0 0.05"/>
      <material name="white">
        <color rgba="1 1 1 1"/>
      </material>
    </visual>
    <collision>
      <geometry>
        <box size="0.2 .3 0.1"/>
      </geometry>
    </collision>
    <inertial>
      <mass value="10"/>
      <inertia ixx="1.0" ixy="0.0" ixz="0.0" iyy="1.0" iyz="0.0" izz="1.0"/>
    </inertial>
  </link>
  <link name="front_left_wheel">
    <visual>
      <geometry>
        <cylinder length="0.05" radius="0.05"/>
      </geometry>
      <!-- <origin rpy="0 1.5 0" xyz="0.1 0.1 0"/> -->
      <origin rpy="0 0 0" xyz="0 0 0"/>
      <material name="black">
        <color rgba="0 0 0 1"/>
      </material>
    </visual>
    <collision>
      <geometry>
        <cylinder length="0.05" radius="0.05"/>
      </geometry>
    </collision>
    <inertial>
      <mass value="1"/>
      <inertia ixx="1.0" ixy="0.0" ixz="0.0" iyy="1.0" iyz="0.0" izz="1.0"/>
    </inertial>
  </link>
  <link name="back_left_wheel">
    <visual>
      <geometry>
        <cylinder length="0.05" radius="0.05"/>
      </geometry>
      <!-- <origin rpy="0 1.5 0" xyz="-0.1 0.1 0"/> -->
      <origin rpy="0 0 0" xyz="0 0 0"/>
      <material name="black">
        <color rgba="0 0 0 1"/>
      </material>
    </visual>
    <collision>
      <geometry>
        <cylinder length="0.05" radius="0.05"/>
      </geometry>
    </collision>
    <inertial>
      <mass value="1"/>
      <inertia ixx="1.0" ixy="0.0" ixz="0.0" iyy="1.0" iyz="0.0" izz="1.0"/>
    </inertial>
  </link>
  <link name="front_right_wheel">
    <visual>
      <geometry>
        <cylinder length="0.05" radius="0.05"/>
      </geometry>
      <!-- <origin rpy="0 1.5 0" xyz="0.1 -0.1 0"/> -->
      <origin rpy="0 0 0" xyz="0 0 0"/>
      <material name="black">
        <color rgba="0 0 0 1"/>
      </material>
    </visual>
    <collision>
      <geometry>
        <cylinder length="0.05" radius="0.05"/>
      </geometry>
    </collision>
    <inertial>
      <mass value="1"/>
      <inertia ixx="1.0" ixy="0.0" ixz="0.0" iyy="1.0" iyz="0.0" izz="1.0"/>
    </inertial>
  </link>
  <link name="back_right_wheel">
    <visual>
      <geometry>
        <cylinder length="0.05" radius="0.05"/>
      </geometry>
      <!-- <origin rpy="0 1.5 0" xyz="-0.1 -0.1 0"/> -->
      <origin rpy="0 0 0" xyz="0 0 0"/>
      <material name="black">
        <color rgba="0 0 0 1"/>
      </material>
    </visual>
    <collision>
      <geometry>
        <cylinder length="0.05" radius="0.05"/>
      </geometry>
    </collision>
    <inertial>
      <mass value="1"/>
      <inertia ixx="1.0" ixy="0.0" ixz="0.0" iyy="1.0" iyz="0.0" izz="1.0"/>
    </inertial>
  </link>
 
  <joint name="base_to_front_left_wheel" type="continuous">
    <axis xyz="0 0 1"/>
    <anchor xyz="0 0 0"/>
    <limit effort="100" velocity="100"/>
    <parent link="base_link"/>
    <child link="front_left_wheel"/>
    <origin rpy="1.5707 0 0" xyz="0.1 0.15 0"/>
  </joint> 
  
  <joint name="base_to_back_left_wheel" type="continuous">
    <parent link="base_link"/>
    <child link="back_left_wheel"/>
    <origin rpy="1.5707 0 0" xyz="-0.1 0.15 0"/>
    <axis xyz="0 0 1"/>
  </joint> 
  
  <joint name="base_to_front_right_wheel" type="continuous">
    <parent link="base_link"/>
     <child link="front_right_wheel"/>
    <axis xyz="0 0 1"/>
   <origin rpy="-1.5707 0 0" xyz="0.1 -0.15 0"/>
  </joint>
  
  <joint name="base_to_back_right_wheel" type="continuous">
    <parent link="base_link"/>
    <child link="back_right_wheel"/>
    <axis xyz="0 0 1"/>
   
    <origin rpy="-1.5707 0 0" xyz="-0.1 -0.15 0"/>
  </joint>
 
    
  <joint name="hokuyo_joint" type="fixed">
    <axis xyz="0 1 0"/>
    <origin rpy="0 0 0" xyz="0.12 0 0.12"/>
    <parent link="base_link"/>
    <child link="hokuyo_link"/>
  </joint>
  <!-- Hokuyo Laser -->
  <link name="hokuyo_link">
    <collision>
      <origin rpy="0 0 0" xyz="0 0 0"/>
      <geometry>
        <box size="0.1 0.1 0.1"/>
      </geometry>
    </collision>
    <visual>
      <origin rpy="0 0 0" xyz="0 0 0"/>
      <geometry>
        <mesh filename="package://robot_with_laser/meshes/hokuyo.dae"/>
      </geometry>
    </visual>
    <inertial>
      <mass value="1e-5"/>
      <origin rpy="0 0 0" xyz="0 0 0"/>
      <inertia ixx="1e-6" ixy="0" ixz="0" iyy="1e-6" iyz="0" izz="1e-6"/>
    </inertial>
  </link>
</robot>

